Workbook

Sheet BT
A1: STT | B1: Vùng | C1: Tỉnh thành | D1: Đói tác | E1: Block | F1: Số HĐ | G1: Tên đầy đủ | H1: Thời gian tạo | I1: Tồn giờ | J1: Hạn còn lại | K1: Ngày hẹn Xanh | L1: Ngày hẹn đỏ | M1: Múi hẹn xanh | N1: Múi hẹn đỏ | O1: Số lần hẹn | P1: CL Lặp | Q1: Loại checklist | R1: Nguồn tạo | S1: Nhân sự | T1: TTCL | U1: TsTc | V1: KH Giục Tiến Độ | W1: Ghi Chú CC | X1: Ghi Chú KTV Gần Nhất | Y1: Gói dịch vụ | Z1: Loại DV | AA1: Độ Ưu Tiên | AB1: Dịch vụ 1 | AC1: TTSCBĐ 1 | AD1: Dịch vụ 2 | AE1: TTSCBĐ 2 | AF1: Dịch vụ 3 | AG1: TTSCBĐ 3 | AH1: Dịch vụ 4 | AI1: TTSCBĐ 4 | AJ1: Dịch vụ 5 | AK1: TTSCBĐ 5 | AL1: POP | AM1: Kiểm soát | AN1: Trưởng bầy
A2: 1 | B2: Tây Bắc Bộ | C2: Tuyên Quang | D2: TQTo TIN | E2: Xa Yen Son-001 | F2: TQFD22274 | G2: PHẠM XUÂN KHÁNH | H2: 16/09/2026 09:30:16 | I2: 196 | J2: -171.867 | L2: 18/09/2026 | N2: 15:30 - 17:30 | O2: 4 | P2: 1 | Q2: Thường | R2: SR-HTKT | S2: TQGTI.TUNGDT4 | T2: Đang XL | U2: TQGP008.0076/HO-5/5-G | W2: 0856593327 kh báo mạng chập chờn, suy hao cao, nhờ kt hỗ trợ | X2: >> TQGTI.TUNGDT4 18/09/2026 17:20:07: kh bao van xu dung bt , duong day lh di theo day trung the qua duong quoc lo kt kothe ha suy hao nua . kh bao van dung ok | Y2: Giga | Z2: Internet | AA2: Support | AB2: Internet | AC2: Có tín hiệu quang nhưng không ổn định / suy hao không đạt chuẩn | AL2: =LEFT(U2,7) -> TQGP008 | AN2: =VLOOKUP(S2,Sheet1!$C:$D,2,0) -> TRANGHT28
A3: 2 | B3: Tây Bắc Bộ | C3: Tuyên Quang | D3: TQTo TIN | E3: Xa Dong Tho-001 | F3: TQAAC9017 | G3: Vũ Đình Khải | H3: 17/09/2026 08:56:48 | I3: 140 | J3: -139.867 | K3: 18/09/2026 | M3: 15:30 - 17:30 | O3: 2 | P3: 2 | Q3: Thường | R3: Tao tu MO | S3: TQGTI.HIEUNV38 | T3: Đang XL | U3: TQGP030.0094/HO-2/2-G | W3: TQAAC9017 - 0966707732 - Số chính chủ: kh bao remote box TH lỗi, ktv thay nhưng giờ sd vẫn lỗi, kh muon hủy hd, nhờ ktv hỗ trợ thay lai thiêt bị | X3: >> TQGTI.HIEUNV38 18/09/2026 11:32:01: chưa có box thay | Y3: Sky | Z3: Internet | AA3: Support | AB3: FPT Play | AC3: Lỗi kết nối BOX và TV (TV không nhận tín hiệu từ Box) | AL3: =LEFT(U3,7) -> TQGP030 | AN3: =VLOOKUP(S3,Sheet1!$C:$D,2,0) -> TQG.HANGVTT12
A4: 3 | B4: Tây Bắc Bộ | C4: Tuyên Quang | D4: TQTo TIN | E4: Phuong My Lam-001 | F4: TQAAE7703 | G4: Lò Thị Ngăn | H4: 20/09/2026 21:27:28 | I4: 88 | J4: -83.917 | L4: 24/09/2026 | N4: 15:30 - 17:30 | O4: 5 | P4: 0 | Q4: Thường | R4: SR-HTKT | S4: TQGTI.THANHNV41 | T4: Đã nhận ca | U4: TQGP014.0196/HO-3/3-G | W4: TQAAE7703 - 0392522890 - Kênh tiếp nhận: live-chat - Sender ID: 6aafecf4a470e - SĐT KH cung cấp: Không ghi nhận - Báo hỏng dịch vụ | Y4: Sky | Z4: Internet | AA4: SOS | AB4: Internet | AC4: Không truy cập được một số dịch vụ hoặc website | AL4: =LEFT(U4,7) -> TQGP014 | AN4: =VLOOKUP(S4,Sheet1!$C:$D,2,0) -> ANHHV15
A5: 4 | B5: Tây Bắc Bộ | C5: Tuyên Quang | D5: TQTo TIN | E5: Xa Nhu Khe-001 | F5: TQFD00989 | G5: Nguyen Huu Phuoc | H5: 20/09/2026 21:49:01 | I5: 68 | J5: -67.867 | K5: 21/09/2026 | M5: 15:30 - 17:30 | O5: 2 | P5: 1 | Q5: Thường | R5: SR - Omni (HiFPT) | S5: TQGTI.CAONB | T5: Đang XL | U5: TQGP005.0041/HO-5/5-G | W5: TQFD00989 - 0853241298 - Nguyen Huu Phuoc: Khách hàng báo không xem được truyền hình, chat OB. Nhờ KT qua kiểm tra giúp | X5: >> TQGTI.CAONB 21/09/2026 15:27:31: khách hàng phản ánh xem ngoại hạng anh bị giật đứng hình, đầu box có kết nối qua ap phụ của kh, kĩ thuật đã bấm lại rj45 kết nối trực tiếp với md chính cho kh, rs lại box. tại thời điểm kta truyền hình đã xem bth ko giật lag | Y5: Giga | Z5: Internet | AA5: Support | AB5: Internet | AC5: Có IP WAN, không truy cập được | AL5: =LEFT(U5,7) -> TQGP005 | AN5: =VLOOKUP(S5,Sheet1!$C:$D,2,0) -> ANHHV15
A6: 5 | B6: Tây Bắc Bộ | C6: Tuyên Quang | D6: TQTo TIN | E6: Phuong My Lam-001 | F6: TQFD13770 | G6: NGUYỄN TIẾN QUẢNG | H6: 21/09/2026 15:31:48 | I6: 27 | J6: -27.367 | K6: 23/09/2026 | M6: 08:00 - 10:00 | O6: 1 | P6: 0 | Q6: Thường | R6: SR-HTKT | S6: TQGTI.THANHNV41 | T6: Đang XL | U6: TQGP014.0027/HO-1/1-G | W6: TQFD13770 - 0395372127 - Kênh tiếp nhận: live-chat - Sender ID: 6ab0e79c3cdfe - SĐT KH cung cấp: Không ghi nhận - Báo hỏng dịch vụ | Y6: Giga | Z6: Internet | AA6: SOS | AB6: Internet | AC6: Không truy cập được một số dịch vụ hoặc website | AL6: =LEFT(U6,7) -> TQGP014 | AN6: =VLOOKUP(S6,Sheet1!$C:$D,2,0) -> ANHHV15
A7: 6 | B7: Tây Bắc Bộ | C7: Tuyên Quang | D7: TQTo TIN | E7: Phuong Binh Thuan-010 | F7: TQAAC6846 | G7: TRƯƠNG THỊ TỴ | H7: 21/09/2026 06:26:08 | I7: 27 | J7: -27.367 | K7: 23/09/2026 | M7: 08:00 - 10:00 | O7: 2 | P7: 0 | Q7: Thường | R7: SR - Omni (HiFPT) | S7: TQGTI.DATNB | T7: Đã PC | U7: TQGP013.0192/HO-6/6-G | W7: Mạng chập chờn, không truy cập được | Y7: Giga | Z7: Internet | AA7: Support | AB7: Internet | AC7: Truy cập mạng chậm hoặc chập chờn | AL7: =LEFT(U7,7) -> TQGP013 | AN7: =VLOOKUP(S7,Sheet1!$C:$D,2,0) -> #N/A
A8: 7 | B8: Tây Bắc Bộ | C8: Tuyên Quang | D8: TQTo TIN | E8: Xa Hung Duc-001 | F8: TQAAC0454 | G8: TRẦN VĂN BÍCH | H8: 22/09/2026 13:43:47 | I8: 25 | J8: -25.367 | K8: 23/09/2026 | M8: 10:00 - 12:00 | O8: 2 | P8: 0 | Q8: Thường | R8: SR-HTKT | S8: TQGTI.BINHTH1 | T8: Đã XL-Đang TD | U8: TQGP024.0219/HO-4/4-G | W8: 0338629504 kh báo mất kết nối , bức xúc do trc đó k biết báo ai, nhờ kt hỗ trợ sớm | Y8: Sky | Z8: Internet | AA8: Support | AB8: Internet | AC8: Không có tín hiệu quang (mkn) | AL8: =LEFT(U8,7) -> TQGP024 | AN8: =VLOOKUP(S8,Sheet1!$C:$D,2,0) -> TRANGHT28
A9: 8 | B9: Tây Bắc Bộ | C9: Tuyên Quang | D9: TQTo TIN | E9: Phuong My Lam-001 | F9: TQAAE4800 | G9: Hoàng Văn Tiến | H9: 23/09/2026 11:10:12 | I9: 26 | J9: -22.2 | L9: 24/09/2026 | N9: 15:30 - 17:30 | O9: 2 | P9: 0 | Q9: Thường | R9: SR-HTKT | S9: TQGTI.ANHPH3 | T9: Đã nhận ca | U9: TQGP013.0233/HO-4/4-G | W9: TQAAE4800 - 0326192565 - Kênh tiếp nhận: live-chat - Sender ID: 6ab350e23b716 - SĐT KH cung cấp: 0326192565 - [Missedcall_notiHiFPT] Báo hỏng dịch vụ | X9: >> TQGTI.ANHPH3 23/09/2026 17:30:20: chua xly kip | Y9: Giga | Z9: Internet | AA9: SOS | AB9: Internet | AC9: Không truy cập được một số dịch vụ hoặc website | AL9: =LEFT(U9,7) -> TQGP013 | AN9: =VLOOKUP(S9,Sheet1!$C:$D,2,0) -> HUONGTT33
A10: 9 | B10: Tây Bắc Bộ | C10: Tuyên Quang | D10: TQTo TIN | E10: Xa Chiem Hoa-001 | F10: TQAAC8160 | G10: CHU VĂN LƯƠNG | H10: 23/09/2026 13:50:45 | I10: 24 | J10: -19.533 | L10: 25/09/2026 | N10: 08:00 - 10:00 | O10: 3 | P10: 0 | Q10: Thường | R10: SR-HTKT | S10: TQGTI.TIENVT3 | T10: Đã nhận ca | U10: TQGP033.0381/HO-5/5-G | W10: TQAAC8160 - 0349716782 - Kênh tiếp nhận: live-chat - Sender ID: 6ab3767e8d3a5 - SĐT KH cung cấp: Không ghi nhận - Báo hỏng dịch vụ | Y10: Sky | Z10: Internet | AA10: SOS | AB10: Internet | AC10: Không truy cập được một số dịch vụ hoặc website | AL10: =LEFT(U10,7) -> TQGP033 | AN10: =VLOOKUP(S10,Sheet1!$C:$D,2,0) -> UYENHT15
A11: 10 | B11: Tây Bắc Bộ | C11: Tuyên Quang | D11: TQTo TIN | E11: Xa Dong Tho-001 | F11: TQAAE1876 | G11: NỊNH VĂN THƯỢNG | H11: 23/09/2026 20:05:45 | I11: 17 | J11: -13.283 | L11: 24/09/2026 | N11: 13:30 - 15:30 | O11: 2 | P11: 0 | Q11: Thường | R11: SR-HTKT | S11: TQGTI.NGHIANV6 | T11: Đã nhận ca | U11: TQGP032.0453/HO-2/2-G | W11: TQAAE1876 - 0347637834 - Kênh tiếp nhận: live-chat - Sender ID: 6ab3ce466d87d - SĐT KH cung cấp: 0357662549 - Báo hỏng dịch vụ | Y11: Sky | Z11: Internet | AA11: SOS | AB11: Internet | AC11: Không truy cập được một số dịch vụ hoặc website | AL11: =LEFT(U11,7) -> TQGP032 | AN11: =VLOOKUP(S11,Sheet1!$C:$D,2,0) -> LYHK7
A12: 11 | B12: Tây Bắc Bộ | C12: Tuyên Quang | D12: TQTo TIN | E12: Xa Phu Luong-001 | F12: TQAAC8944 | G12: BÙI THANH TÙNG | H12: 23/09/2026 09:11:32 | I12: 28 | J12: -4.183 | L12: 24/09/2026 | N12: 13:30 - 15:30 | O12: 4 | P12: 0 | Q12: Thường | R12: SR-HTKT | S12: TQGTI.QUYETNT1 | T12: Đã nhận ca | U12: TQGP032.0160/HO-3/3-G | W12: 0983126725 kh báo mạng cc | Y12: Sky | Z12: Internet | AA12: Support | AB12: Internet | AC12: KH yêu cầu di chuyển Modem | AL12: =LEFT(U12,7) -> TQGP032 | AN12: =VLOOKUP(S12,Sheet1!$C:$D,2,0) -> TAMVTT5
A13: 12 | B13: Tây Bắc Bộ | C13: Tuyên Quang | D13: TQTo TIN | E13: Xa Son Duong-002 | F13: TQAAB1898 | G13: Dùng Văn Thọ | H13: 23/09/2026 17:36:50 | I13: 1 | J13: -1.367 | K13: 24/09/2026 | M13: 10:00 - 12:00 | O13: 1 | P13: 0 | Q13: Thường | R13: SR-HTKT | S13: TQGTI.GIANGLV2 | T13: Đang XL | U13: TQGP021.0125/HO-10/10-G | W13: Kh muốn mua điều khiển nhờ KT hỗ trợ | X13: >> TQG.HangVTT12 24/09/2026 09:34:14: nhờ KT thu luôn tiền cước cho KH giúp | Y13: Giga | Z13: Internet | AA13: Support | AB13: Internet | AC13: KH cần thay/ lắp đặt/ cài đặt thiết bị modem, AP, Box, Camera | AL13: =LEFT(U13,7) -> TQGP021 | AN13: =VLOOKUP(S13,Sheet1!$C:$D,2,0) -> TQG.HANGVTT12
A14: 13 | B14: Tây Bắc Bộ | C14: Tuyên Quang | D14: TQTo TIN | E14: Xa Ham Yen-001 | F14: TQAAC6838 | G14: ĐỖ VĂN THẮNG | H14: 24/09/2026 06:20:41 | I14: 1 | J14: -1.367 | K14: 24/09/2026 | M14: 10:00 - 12:00 | O14: 1 | P14: 0 | Q14: Thường | R14: SR - Omni | S14: TQGTI.CAOTT | T14: Đang XL | U14: TQGP029.0456/HO-1/1-G | W14: TQAAC6838 - 0354998185 - DO VAN THANG:KH báo mất tín hiệu, tình trạng Enable- Offline- LOSi,đèn los báo đỏ, tắt bật lại modem, NOK, nhờ KT care | Y14: Sky | Z14: Internet | AA14: Support | AB14: Internet | AC14: Không có tín hiệu quang (mkn) | AL14: =LEFT(U14,7) -> TQGP029 | AN14: =VLOOKUP(S14,Sheet1!$C:$D,2,0) -> UYENHT15
A15: 14 | B15: Tây Bắc Bộ | C15: Tuyên Quang | D15: TQTo TIN | E15: Xa Dong Tho-001 | F15: TQAAA6929 | G15: TRẦN VĂN ĐỨC | H15: 23/09/2026 14:32:00 | I15: 1 | J15: -1.367 | K15: 24/09/2026 | M15: 10:00 - 12:00 | O15: 2 | P15: 0 | Q15: Thường | R15: SR - HiFPT | S15: TQGTI.HIEUNV38 | T15: Đang XL | U15: TQGP017.0196/HO-6/6-G | W15: Checklist app hifpt/ Mạng chập chờn, không truy cập được/ liên hệ số 0346253654 | Y15: Giga | Z15: Internet | AA15: Support | AB15: Internet | AC15: Không có tín hiệu quang (mkn) | AL15: =LEFT(U15,7) -> TQGP017 | AN15: =VLOOKUP(S15,Sheet1!$C:$D,2,0) -> TQG.HANGVTT12
A16: 15 | B16: Tây Bắc Bộ | C16: Tuyên Quang | D16: TQTo TIN | E16: Phuong My Lam-001 | F16: TQAAB2673 | G16: TRẦN THỊ THƯỜNG | H16: 23/09/2026 15:28:25 | I16: 22 | J16: 2.1 | L16: 24/09/2026 | N16: 15:30 - 17:30 | O16: 2 | P16: 0 | Q16: Thường | R16: SR-HTKT | S16: TQGTI.THANHNV41 | T16: Đã nhận ca | U16: TQGP013.0220/HO-7/7-G | W16: 0868078228 KH cần cài đặt lại box. nhờ kt kiểm tra và thu luôn giúp cus tiền cước 1tr320 6T | Y16: Giga | Z16: Internet | AA16: Support | AB16: Internet | AC16: KH báo mất Modem | AL16: =LEFT(U16,7) -> TQGP013 | AN16: =VLOOKUP(S16,Sheet1!$C:$D,2,0) -> ANHHV15
A17: 16 | B17: Tây Bắc Bộ | C17: Tuyên Quang | D17: TQTo TIN | E17: Phuong An Tuong-001 | F17: TQAAC7974 | G17: HÀ VĂN TUY | H17: 23/09/2026 15:51:04 | I17: -2 | J17: 2.133 | K17: 24/09/2026 | M17: 13:30 - 15:30 | O17: 2 | P17: 0 | Q17: Thường | R17: SR - Omni (HiFPT) | S17: TQGTI.GIANGVH2 | T17: Đã nhận ca | U17: TQGP005.0141/HO-3/3-G | W17: Mini app -- | X17: >> TQGTI.GIANGVH2 23/09/2026 17:08:02: hẹn lại | Y17: Sky | Z17: Internet | AA17: Support | AB17: FPT Play | AC17: Truyền hình không xem được tất cả kênh | AL17: =LEFT(U17,7) -> TQGP005 | AN17: =VLOOKUP(S17,Sheet1!$C:$D,2,0) -> ANHHV15
A18: 17 | B18: Tây Bắc Bộ | C18: Tuyên Quang | D18: TQTo TIN | E18: Xa Son Duong-001 | F18: TQFD14202 | G18: TRẦN THỊ DUNG | H18: 24/09/2026 09:56:17 | I18: -2 | J18: 2.133 | K18: 24/09/2026 | M18: 13:30 - 15:30 | O18: 2 | P18: 0 | Q18: Thường | R18: SR-HTKT | S18: TQGTI.HANHPB | T18: Đã nhận ca | U18: TQGP011.0041/HO-1/1-G | W18: 0334069995 KH báo mkn nhờ KT qua kiểm tra | Y18: Giga | Z18: Internet | AA18: Support | AB18: Internet | AC18: Không có tín hiệu quang (mkn) | AL18: =LEFT(U18,7) -> TQGP011 | AN18: =VLOOKUP(S18,Sheet1!$C:$D,2,0) -> TQG.HANGVTT12
A19: 18 | B19: Tây Bắc Bộ | C19: Tuyên Quang | D19: TQTo TIN | E19: Xa Phu Luong-001 | F19: TQAAB1352 | G19: CHU VĂN CHIẾN | H19: 23/09/2026 21:18:41 | I19: -2 | J19: 2.133 | K19: 24/09/2026 | M19: 13:30 - 15:30 | O19: 1 | P19: 0 | Q19: Thường | R19: SR-HTKT | S19: TQGTI.QUANHV1 | T19: Đã nhận ca | U19: TQGP027.0217/HO-6/6-G | W19: TQAAB1352 - 0974544558 - Kênh tiếp nhận: live-chat - Sender ID: 0974544558 - SĐT KH cung cấp: Không ghi nhận - Báo hỏng dịch vụ | Y19: Giga | Z19: Internet | AA19: SOS | AB19: Internet | AC19: Không truy cập được một số dịch vụ hoặc website | AL19: =LEFT(U19,7) -> TQGP027 | AN19: =VLOOKUP(S19,Sheet1!$C:$D,2,0) -> TAMVTT5
A20: 19 | B20: Tây Bắc Bộ | C20: Tuyên Quang | D20: TQTo TIN | E20: Xa Phu Luong-001 | F20: TQAAB9349 | G20: NGUYỄN MINH HIỀN | H20: 23/09/2026 17:36:56 | I20: -2 | J20: 2.133 | K20: 24/09/2026 | M20: 13:30 - 15:30 | O20: 1 | P20: 0 | Q20: Thường | R20: SR-HTKT | S20: TQGTI.QUYETNT1 | T20: Đã nhận ca | U20: TQGP031.0167/HO-5/5-G | W20: Kh báo mkn | Y20: Giga | Z20: Internet | AA20: Support | AB20: Internet | AC20: Không có tín hiệu quang (mkn) | AL20: =LEFT(U20,7) -> TQGP031 | AN20: =VLOOKUP(S20,Sheet1!$C:$D,2,0) -> TAMVTT5
A21: 20 | B21: Tây Bắc Bộ | C21: Tuyên Quang | D21: TQTo TIN | E21: Xa Son Duong-002 | F21: TQAAA1264 | G21: TRẦN THỊ THÌN | H21: 24/09/2026 11:33:47 | I21: -2 | J21: 2.133 | K21: 24/09/2026 | M21: 13:30 - 15:30 | O21: 1 | P21: 0 | Q21: Thường | R21: SR-HTKT | S21: TQGTI.GIANGLV2 | T21: Đã nhận ca | U21: TQGP023.0166/HO-6/6-G | W21: 0378768114 KH báo bị sét đánh cháy dây đầu box, wf thì vẫn sd đc nhưng tivi k xem đc nhờ KT qua kiểm tra | Y21: Giga | Z21: Internet | AA21: Support | AB21: FPT Play | AC21: Lỗi hệ thống FPT Play - Không xem được phim truyện/ Truyền hình | AL21: =LEFT(U21,7) -> TQGP023 | AN21: =VLOOKUP(S21,Sheet1!$C:$D,2,0) -> TQG.HANGVTT12
A22: 21 | B22: Tây Bắc Bộ | C22: Tuyên Quang | D22: TQTo TIN | E22: Xa Yen Son-001 | F22: TQAAE3863 | G22: HÀ THỊ ĐÀN | H22: 22/09/2026 08:14:40 | I22: -2 | J22: 2.133 | K22: 24/09/2026 | L22: 23/09/2026 | M22: 13:30 - 15:30 | N22: 15:30 - 17:30 | O22: 4 | P22: 0 | Q22: Thường | R22: SR-HTKT | S22: TQGTI.CUONGDD9 | T22: Đã nhận ca | U22: TQGP038.0403/HO-1/1-G | W22: 0865929712 kh báo MTH k truy cập đc nhờ KT hỗ trợ | Z22: Internet | AA22: Support | AB22: Internet | AC22: Không có tín hiệu quang (mkn) | AL22: =LEFT(U22,7) -> TQGP038 | AN22: =VLOOKUP(S22,Sheet1!$C:$D,2,0) -> TRANGDTH35
A23: 22 | B23: Tây Bắc Bộ | C23: Tuyên Quang | D23: TQTo TIN | E23: Xa Ham Yen-001 | F23: TQAAA3007 | G23: ĐINH THỊ TUYÊN | H23: 24/09/2026 10:21:50 | I23: -2 | J23: 2.133 | K23: 24/09/2026 | M23: 13:30 - 15:30 | O23: 1 | P23: 0 | Q23: Thường | R23: SR-HTKT | S23: TQGTI.TUANLQ2 | T23: Đã PC | U23: TQGP028.0124/HO-1/1-G | W23: 0363527234 kh cần kết nối box | Y23: Giga | Z23: Internet | AA23: Support | AB23: FPT Play | AC23: KH cần thay/ lắp đặt, kết nối BOX | AL23: =LEFT(U23,7) -> TQGP028 | AN23: =VLOOKUP(S23,Sheet1!$C:$D,2,0) -> UYENHT15
A24: 23 | B24: Tây Bắc Bộ | C24: Tuyên Quang | D24: TQTo TIN | E24: Phuong Minh Xuan-001 | F24: TQFD23415 | G24: PHẠM XUÂN HOÀN | H24: 23/09/2026 13:39:00 | I24: -2 | J24: 2.133 | K24: 24/09/2026 | M24: 13:30 - 15:30 | O24: 1 | P24: 0 | Q24: Thường | R24: SR-HTKT | S24: TQGTI.DANGNV | T24: Đã nhận ca | U24: TQGP006.0245/HO-4/4-G | W24: 0376038881 kh báo MTh k truy cập đc nhờ KT hỗ trợ | Y24: Giga | Z24: Internet | AA24: Support | AB24: Internet | AC24: Không có tín hiệu quang (mkn) | AL24: =LEFT(U24,7) -> TQGP006 | AN24: =VLOOKUP(S24,Sheet1!$C:$D,2,0) -> TRANGHT28
A25: 24 | B25: Tây Bắc Bộ | C25: Tuyên Quang | D25: TQTo TIN | E25: Xa Dong Tho-001 | F25: TQFD15425 | G25: VI VĂN QUANG | H25: 23/09/2026 18:51:08 | I25: -2 | J25: 2.133 | K25: 24/09/2026 | M25: 13:30 - 15:30 | O25: 2 | P25: 0 | Q25: Thường | R25: SR - Omni | S25: TQGTI.HIEUNV38 | T25: Đã nhận ca | U25: TQGP021.0116/HO-9/9- | W25: TQFD15425 - 0966467769 - Chd: | Y25: Sky | Z25: Internet | AA25: Support | AB25: Internet | AC25: Không có tín hiệu quang (mkn) | AL25: =LEFT(U25,7) -> TQGP021 | AN25: =VLOOKUP(S25,Sheet1!$C:$D,2,0) -> TQG.HANGVTT12
A26: 25 | B26: Tây Bắc Bộ | C26: Tuyên Quang | D26: TQTo TIN | E26: Xa Son Duong-001 | F26: TQAAC1859 | G26: PHÙNG VĂN TOÀN | H26: 24/09/2026 11:16:10 | I26: -2 | J26: 2.133 | K26: 24/09/2026 | M26: 13:30 - 15:30 | O26: 1 | P26: 0 | Q26: Thường | R26: SR-HTKT | S26: TQGTI.CONGND4 | T26: Đã nhận ca | U26: TQGP022.0096/HO-4/4-G | W26: 0982545280 kh baó MTH k truy cập đc nhờ KT hỗ trợ | Y26: Giga | Z26: Internet | AA26: Support | AB26: Internet | AC26: Không có tín hiệu quang (mkn) | AL26: =LEFT(U26,7) -> TQGP022 | AN26: =VLOOKUP(S26,Sheet1!$C:$D,2,0) -> LYHK7
A27: 26 | B27: Tây Bắc Bộ | C27: Tuyên Quang | D27: TQTo TIN | E27: Xa Phu Luong-001 | F27: TQAAB6047 | G27: NGUYỄN VĂN LA | H27: 23/09/2026 20:35:51 | I27: -2 | J27: 2.133 | K27: 24/09/2026 | M27: 13:30 - 15:30 | O27: 1 | P27: 0 | Q27: Thường | R27: SR-HTKT | S27: TQGTI.QUYETNT1 | T27: Đã nhận ca | U27: TQGP031.0157/HO-5/5-G | W27: TQAAB6047 - 0977118907 - Kênh tiếp nhận: live-chat - Sender ID: 6ab3d57155950 - SĐT KH cung cấp: Không ghi nhận - Báo hỏng dịch vụ | Y27: Giga | Z27: Internet | AA27: SOS | AB27: Internet | AC27: Không truy cập được một số dịch vụ hoặc website | AL27: =LEFT(U27,7) -> TQGP031 | AN27: =VLOOKUP(S27,Sheet1!$C:$D,2,0) -> TAMVTT5
A28: 27 | B28: Tây Bắc Bộ | C28: Tuyên Quang | D28: TQTo TIN | E28: Xa Phu Luong-001 | F28: TQAAA3859 | G28: LIỄU THỊ HÀ | H28: 23/09/2026 20:15:04 | I28: -2 | J28: 2.133 | K28: 24/09/2026 | M28: 13:30 - 15:30 | O28: 1 | P28: 0 | Q28: Thường | R28: SR - Omni | S28: TQGTI.BINHLV6 | T28: Đã PC | U28: TQGP027.0119/HO-2/2-G | W28: TQAAA3859 - 0378457751 - LIỄU THỊ HÀ: | Y28: Giga | Z28: Internet | AA28: Support | AB28: Internet | AC28: Không có tín hiệu quang (mkn) | AL28: =LEFT(U28,7) -> TQGP027 | AN28: =VLOOKUP(S28,Sheet1!$C:$D,2,0) -> TAMVTT5
A29: 28 | B29: Tây Bắc Bộ | C29: Tuyên Quang | D29: TQTo TIN | E29: Xa Ham Yen-001 | F29: TQAAC8589 | G29: THẢO THỊ SUA | H29: 23/09/2026 08:01:49 | I29: -2 | J29: 2.133 | K29: 24/09/2026 | M29: 13:30 - 15:30 | O29: 3 | P29: 0 | Q29: Thường | R29: SR-HTKT | S29: TQGTI.LUCMDC | T29: Đã nhận ca | U29: TQGP028.0348/HO-6/6-G | W29: 0372267714 kh bao mạng kém sd lúc được lúc k | Y29: Sky | Z29: Internet | AA29: Support | AB29: Internet | AC29: WiFi sóng yếu hoặc chập chờn | AL29: =LEFT(U29,7) -> TQGP028 | AN29: =VLOOKUP(S29,Sheet1!$C:$D,2,0) -> UYENHT15
A30: 29 | B30: Tây Bắc Bộ | C30: Tuyên Quang | D30: TQTo TIN | E30: Xa Nhu Khe-001 | F30: TQAAC6416 | G30: PHÙNG HOÀI THU | H30: 23/09/2026 21:48:30 | I30: -2 | J30: 2.133 | K30: 24/09/2026 | M30: 13:30 - 15:30 | O30: 1 | P30: 0 | Q30: Thường | R30: SR - Omni (HiFPT) | S30: TQGTI.KHANHLQ1 | T30: Đã nhận ca | U30: TQGP016.0200/HO-4/4-G | W30: ko báo khi có người | Y30: Giga | Z30: Internet | AA30: Support | AB30: Internet | AC30: Có IP WAN, không truy cập được | AL30: =LEFT(U30,7) -> TQGP016 | AN30: =VLOOKUP(S30,Sheet1!$C:$D,2,0) -> ANHHV15
A31: 30 | B31: Tây Bắc Bộ | C31: Tuyên Quang | D31: TQTo TIN | E31: Xa Son Duong-001 | F31: TQFD11069 | G31: NGUYỄN THÀNH TRUNG | H31: 24/09/2026 10:24:45 | I31: -2 | J31: 2.133 | K31: 24/09/2026 | M31: 13:30 - 15:30 | O31: 1 | P31: 0 | Q31: Thường | R31: SR-HTKT | S31: TQGTI.HANHPB | T31: Đã nhận ca | U31: TQGP011.0135/HO-1/1-G | W31: 0395129786 kh báo k xem đc TH nhờ KT hỗ trợ | Y31: Giga | Z31: Internet | AA31: Support | AB31: FPT Play | AC31: Truyền hình không xem được một vài kênh | AL31: =LEFT(U31,7) -> TQGP011 | AN31: =VLOOKUP(S31,Sheet1!$C:$D,2,0) -> TQG.HANGVTT12
A32: 31 | B32: Tây Bắc Bộ | C32: Tuyên Quang | D32: TQTo TIN | E32: Xa Yen Son-001 | F32: TQAAC7840 | G32: PHẠM ĐÌNH CHI | H32: 23/09/2026 07:30:30 | I32: -2 | J32: 2.133 | K32: 24/09/2026 | M32: 13:30 - 15:30 | O32: 1 | P32: 0 | Q32: Thường | R32: SR-HTKT | S32: TQGTI.TUNGDT4 | T32: Đang XL | U32: TQGP008.0248/HO-7/7-G | W32: TQAAC7840 - 0963212839 - Kênh tiếp nhận: live-chat - Sender ID: 6ab31d5b87743 - SĐT KH cung cấp: Không ghi nhận - Báo hỏng dịch vụ | Y32: Sky | Z32: Internet | AA32: SOS | AB32: Internet | AC32: Không truy cập được một số dịch vụ hoặc website | AL32: =LEFT(U32,7) -> TQGP008 | AN32: =VLOOKUP(S32,Sheet1!$C:$D,2,0) -> TRANGHT28
A33: 32 | B33: Tây Bắc Bộ | C33: Tuyên Quang | D33: TQTo TIN | E33: Xa Phu Luong-001 | F33: TQAAA3950 | G33: PHAN VĂN THÀNH | H33: 23/09/2026 14:20:41 | I33: -2 | J33: 2.133 | K33: 24/09/2026 | M33: 13:30 - 15:30 | O33: 2 | P33: 0 | Q33: Thường | R33: SR - Omni | S33: TQGTI.BINHLV6 | T33: Đã nhận ca | U33: TQGP027.0127/HO-3/3-G | W33: TQAAA3950 - 0969962090 - PHAN VĂN THÀNH: | Y33: Giga | Z33: Internet | AA33: Support | AB33: FPT Play | AC33: Lỗi không sử dụng được tính năng điều khiển giọng nói | AL33: =LEFT(U33,7) -> TQGP027 | AN33: =VLOOKUP(S33,Sheet1!$C:$D,2,0) -> TAMVTT5
A34: 33 | B34: Tây Bắc Bộ | C34: Tuyên Quang | D34: TQTo TIN | E34: Phuong An Tuong-001 | F34: TQAAF0785 | G34: Lê Khánh Ly | H34: 24/09/2026 12:31:09 | I34: -2 | J34: 2.133 | K34: 24/09/2026 | M34: 13:30 - 15:30 | O34: 1 | P34: 0 | Q34: Thường | R34: SR-HTKT | S34: TQGTI.CUONGLM8 | T34: Đã PC | U34: TQGP007.0123/HO-2/2-G | W34: TQAAF0785 - 0904204817 - Kênh tiếp nhận: live-chat - Sender ID: 6ab4b50d1caaf - SĐT KH cung cấp: 0904204817 - Báo hỏng dịch vụ | Y34: Sky | Z34: Internet | AA34: SOS | AB34: Internet | AC34: Không truy cập được một số dịch vụ hoặc website | AL34: =LEFT(U34,7) -> TQGP007 | AN34: =VLOOKUP(S34,Sheet1!$C:$D,2,0) -> LYHK7
A35: 34 | B35: Tây Bắc Bộ | C35: Tuyên Quang | D35: TQTo TIN | E35: Phuong Minh Xuan-001 | F35: TQFD08716 | G35: TRẦN THỊ THÚY | H35: 23/09/2026 17:28:51 | I35: 20 | J35: 4.1 | L35: 24/09/2026 | N35: 13:30 - 15:30 | O35: 2 | P35: 0 | Q35: Thường | R35: SR-HTKT | S35: TQGTI.NAMVD2 | T35: Đã nhận ca | U35: TQGP004.0215/HO-8/8-G | W35: 0346562669 KH báo mkn mạng, nhờ KT xử lý | Y35: Giga | Z35: Internet | AA35: Support | AB35: Internet | AC35: Không có tín hiệu quang (mkn) | AL35: =LEFT(U35,7) -> TQGP004 | AN35: =VLOOKUP(S35,Sheet1!$C:$D,2,0) -> TRANGDTH35
A36: 35 | B36: Tây Bắc Bộ | C36: Tuyên Quang | D36: TQTo TIN | E36: Xa Dong Tho-001 | F36: TQAAC6077 | G36: RIÊU VĂN DOANH | H36: 23/09/2026 18:50:25 | I36: -4 | J36: 4.133 | K36: 24/09/2026 | M36: 15:30 - 17:30 | O36: 2 | P36: 0 | Q36: Thường | R36: SR-HTKT | S36: TQGTI.HIEUNV38 | T36: Đã nhận ca | U36: TQGP018.0144/HO-7/7-G | W36: TQAAC6077 - 0986492110 - Kênh tiếp nhận: live-chat - Sender ID: 6ab3bcc043e3a - SĐT KH cung cấp: Không ghi nhận - Báo hỏng dịch vụ | Y36: Giga | Z36: Internet | AA36: SOS | AB36: Internet | AC36: Không truy cập được một số dịch vụ hoặc website | AL36: =LEFT(U36,7) -> TQGP018 | AN36: =VLOOKUP(S36,Sheet1!$C:$D,2,0) -> TQG.HANGVTT12
A37: 36 | B37: Tây Bắc Bộ | C37: Tuyên Quang | D37: TQTo TIN | E37: Phuong Minh Xuan-001 | F37: TQFD02723 | G37: Nguyen Thi Hue | H37: 23/09/2026 14:09:24 | I37: -4 | J37: 4.133 | K37: 24/09/2026 | L37: 23/09/2026 | M37: 15:30 - 17:30 | N37: 13:30 - 15:30 | O37: 2 | P37: 0 | Q37: Thường | R37: SR-HTKT | S37: TQGTI.DANGNV | T37: Đã nhận ca | U37: TQGP006.0072/HO-5/5-G | W37: kh xem đc cam nhờ KTV qua hỗ trợ cho kh | Y37: Giga | Z37: Internet | AA37: Support | AB37: FPT Camera Combo | AC37: [CMR] KH không nhận được OTP | AL37: =LEFT(U37,7) -> TQGP006 | AN37: =VLOOKUP(S37,Sheet1!$C:$D,2,0) -> TRANGHT28
A38: 37 | B38: Tây Bắc Bộ | C38: Tuyên Quang | D38: TQTo TIN | E38: Xa Ham Yen-001 | F38: TQAAE0541 | G38: Ma Công Vệ | H38: 21/09/2026 15:06:01 | I38: -4 | J38: 4.133 | K38: 24/09/2026 | M38: 15:30 - 17:30 | O38: 6 | P38: 0 | Q38: Thường | R38: SR-HTKT | S38: TQGTI.HUNGCV4 | T38: Đã nhận ca | U38: TQGP037.0190/HO-1/1-G | W38: 0342002622 kh báo đứt dây | Y38: Sky | Z38: Internet | AA38: Support | AB38: Internet | AC38: Không có tín hiệu quang (mkn) | AL38: =LEFT(U38,7) -> TQGP037 | AN38: =VLOOKUP(S38,Sheet1!$C:$D,2,0) -> UYENHT15
A39: 38 | B39: Tây Bắc Bộ | C39: Tuyên Quang | D39: TQTo TIN | E39: Xa Dong Tho-001 | F39: TQAAA9185 | G39: ĐỖ NGỌC HÙNG | H39: 24/09/2026 09:18:09 | I39: -4 | J39: 4.133 | K39: 24/09/2026 | M39: 15:30 - 17:30 | O39: 1 | P39: 0 | Q39: Thường | R39: SR - Omni (HiFPT) | S39: TQGTI.NGHIANV6 | T39: Đã nhận ca | U39: TQGP030.0132/HO-4/4-G | W39: Mini app -- | Z39: Internet | AA39: Support | AB39: Internet | AC39: KH yêu cầu di chuyển dây thuê bao (lastmile) | AL39: =LEFT(U39,7) -> TQGP030 | AN39: =VLOOKUP(S39,Sheet1!$C:$D,2,0) -> LYHK7
A40: 39 | B40: Tây Bắc Bộ | C40: Tuyên Quang | D40: TQTo TIN | E40: Phuong My Lam-001 | F40: TQAAE5855 | G40: Trần Thị Hà | H40: 23/09/2026 11:42:15 | I40: -4 | J40: 4.133 | K40: 24/09/2026 | M40: 15:30 - 17:30 | O40: 1 | P40: 0 | Q40: Thường | R40: SR-HTKT | S40: TQGTI.ANHPH3 | T40: Đã PC | U40: TQGP013.0048/HO-6/6-G | W40: TQAAE5855 - 0987682243 - Kênh tiếp nhận: live-chat - Sender ID: 6ab3585b8578f - SĐT KH cung cấp: Không ghi nhận - Báo hỏng dịch vụ | Y40: Sky | Z40: Internet | AA40: SOS | AB40: Internet | AC40: Không truy cập được một số dịch vụ hoặc website | AL40: =LEFT(U40,7) -> TQGP013 | AN40: =VLOOKUP(S40,Sheet1!$C:$D,2,0) -> HUONGTT33
...

Sheet TK
A1: STT | B1: Vùng | C1: Tỉnh thành | D1: Số HĐ | E1: Đối tác | F1: Block | G1: Tên KH | H1: Tình trạng HĐ | I1: Gói dịch vụ | J1: Đơn hàng & Dịch Vụ | K1: Tình trạng | L1: TG tạo PTC | M1: Loại triển khai | N1: Thông số thi công | O1: Lý do không tạo được PTC | P1: Sale HĐ | Q1: Block nhân sự | R1: Nhân sự | S1: TG Hẹn xanh | T1: TG Hẹn đỏ | U1: Tên truy cập | V1: Ghi chú triển khai TIN/PNC | W1: Quản lý
A2: 1 | B2: 11.Tay Bac Bo | C2: Tuyên Quang | D2: TQAAF1352 | E2: TIN TQG | F2: Xa Hung Duc-001- L01 | G2: Ly Thi Huyen | H2: Bình thường | I2: Giga | J2: TQGP40061T55:FPT Camera Combo, FPT Play, Internet | K2: Đã nhận ca | L2: 04-09-2026 13:16:04 | M2: Triển khai mới | N2: TQGP024.0421/HO-8/8-G | P2: tqg.tuenv3 | Q2: Xa Hung Duc-001 | R2: TQGTI.BINHTH1 | T2: 27-09-2026 19:30:00 | U2: Tqfdl-260904-1352 | V2: kh đi vắng mấy hôm. hẹn khi nào về kh gọi>>(TQGTI.BINHTH1 04/09/2026 10:18:17 PM) | W2: =VLOOKUP(R2,Sheet1!$C:$D,2,0) -> TRANGHT28
A3: 2 | B3: 11.Tay Bac Bo | C3: Tuyên Quang | D3: TQAAC3881 | E3: TIN TQG | F3: Xa Hung Duc-001- L01 | G3: TUONG VAN CHINH | H3: Bình thường | I3: Giga | J3: TQGP80063CME:FPT Camera Combo | K3: Đang xử lý | L3: 08-09-2026 09:07:03 | M3: KH nâng cấp dịch vụ gia tăng | N3: TQGP024.0325/HO-5/5-G | P3: hni.huongbt9 | Q3: Xa Hung Duc-001 | R3: TQGTI.BINHTH1 | T3: 27-09-2026 19:30:00 | U3: Tqfdl-250331-3881 | V3: kh bảo hôm nào có lương alo qua lắp>>(TQGTI.BINHTH1 22/09/2026 01:47:44 PM) kh hẹn có lương>>(TQGTI.BINHTH1 20/09/2026 05:32:59 PM) chưa có cam 4s>>(TQGTI.BINHTH1 15/09/2026 04:59:28 PM) kho hết cam 4s. đang đợi điều chuyển>>(TQGTI.BINHTH1 10/09/2026 08:11:12 AM) | W3: =VLOOKUP(R3,Sheet1!$C:$D,2,0) -> TRANGHT28
A4: 3 | B4: 11.Tay Bac Bo | C4: Tuyên Quang | D4: TQAAC8438 | E4: TIN TQG | F4: Xa Hung Duc-001- L01 | G4: LE THI TUYET | H4: Bình thường | I4: Sky | J4: TQGP80063HSM:FPT Camera Combo | K4: Đã phân công | L4: 08-09-2026 17:47:20 | M4: KH nâng cấp dịch vụ gia tăng | N4: TQGP025.0171/HO-8/8-G | P4: hni.anhhp5 | Q4: Xa Hung Duc-001 | R4: TQGTI.BINHTH1 | S4: 28-09-2026 10:00:00 | U4: Tqfdl-250917-8438 | W4: =VLOOKUP(R4,Sheet1!$C:$D,2,0) -> TRANGHT28
A5: 4 | B5: 11.Tay Bac Bo | C5: Tuyên Quang | D5: TQAAF1563 | E5: TIN TQG | F5: Phuong Minh Xuan-001- L05 | G5: Ly Van Nguyen | H5: Bình thường | I5: Giga | J5: TQGP90063QKB:FPT Camera Combo, FPT Play, Internet | K5: Đã nhận ca | L5: 09-09-2026 15:11:55 | M5: Triển khai mới | N5: TQGP009.0251/HO-V/V-G | P5: tqg.hatt47 | Q5: Phuong Minh Xuan-001 | R5: TQGTI.TUANQD | S5: 30-09-2026 17:30:00 | U5: Tqfdl-260909-1563 | V5: khg đi viện chưa về>>(TQGTI.TUANQD 20/09/2026 02:46:21 PM) | W5: =VLOOKUP(R5,Sheet1!$C:$D,2,0) -> TRANGDTH35
A6: 5 | B6: 11.Tay Bac Bo | C6: Tuyên Quang | D6: TQAAE8588 | E6: TIN TQG | F6: Phuong Minh Xuan-001- L04 | G6: Vu Hai Nam | H6: Bình thường | I6: Sky | J6: SSR-TQAAE8588-TDDDNN100926QOT5:FPT Camera, FPT Play, Internet | K6: Đã nhận ca | L6: 10-09-2026 17:39:42 | M6: Chuyển địa điểm | N6: TQGP004.0076/HO-3/3-G | P6: trangdth35 | Q6: Phuong Minh Xuan-001 | R6: TQGTI.THANHNV8 | S6: 24-09-2026 17:30:00 | U6: Tqfdl-260630-8588 | V6: kh vẫn chưa lấy được chìa khoá>>(TQGTI.THANHNV8 17/09/2026 04:09:30 PM) kh hẹn>>(TQGTI.THANHNV8 14/09/2026 04:10:04 PM) kh vẫn chưa lấy được chìa khoá nhà>>(TQGTI.THANHNV8 12/09/2026 03:59:36 PM) kh hẹn>>(TQGTI.THANHNV8 11/09/2026 05:20:49 PM) kh hẹn>>(TQGTI.THANHNV8 11/09/2026 10:33:53 AM) | W6: =VLOOKUP(R6,Sheet1!$C:$D,2,0) -> TRANGDTH35
A7: 6 | B7: 11.Tay Bac Bo | C7: Tuyên Quang | D7: TQAAF1606 | E7: TIN TQG | F7: Xa Chiem Hoa-001- L04 | G7: NGuyen Van Binh | H7: Bình thường | I7: Giga | J7: TQGPB00648F4:FPT Camera Combo, FPT Play, Internet | K7: Đã nhận ca | L7: 11-09-2026 10:46:59 | M7: Triển khai mới | N7: TQGP033.0266/HO-1/1-G | P7: tqg.chungnd7 | Q7: Xa Chiem Hoa-001 | R7: TQGTI.TIENVT3 | S7: 26-09-2026 10:00:00 | U7: Tqfdl-260911-1606 | V7: Nhà kh đang thi công , chưa có điện , hẹn ngày 17 thi công>>(TQGTI.TIENVT3 14/09/2026 02:42:16 PM) Phân tuyến trên Inside TQGTI.CHIENMM>>(Hahh.tin 14/09/2026 09:43:47 AM) | W7: =VLOOKUP(R7,Sheet1!$C:$D,2,0) -> UYENHT15
A8: 7 | B8: 11.Tay Bac Bo | C8: Tuyên Quang | D8: TQAAF1594 | E8: TIN TQG | F8: Xa Yen Son-001- L02 | G8: Do Thi Ha | H8: Bình thường | I8: Giga | J8: TQGPC0064RN6:FPT Camera Combo, FPT Play, Internet | K8: Đã phân công | L8: 12-09-2026 22:10:47 | M8: Triển khai mới | N8: TQGP008.0245/HO-1/1-G | P8: hni.huyennt306 | Q8: Phuong Minh Xuan-001 | R8: TQGTI.NAMVD2 | S8: 25-09-2026 12:00:00 | U8: Tqfdl-260912-1594 | V8: Phân tuyến trên Inside TQGTI.NAMVD2>>(Nghiavm1.tin 22/09/2026 02:03:22 PM) Phân tuyến trên Inside TQGTI.NAMVD2>>(Nghiavm1.tin 15/09/2026 10:01:33 AM) Micro-PTC-NOT-OK(TQGTI.NAMVD2) - 14/09/2026 13:46:35; -> ; Chuyển thi công-hni.huyennt306-14/09/2026 13:57:46-SaleClub: nhà khách có đám hiêú nên khách hẹn cuối tháng xong công việc lắp ;Micro-PTC-NOT-OK(TQGTI.NAMVD2) - 18/09/2026 11:44:00; -> ; Chuyển thi công-hni.huyennt306-19/09/2026 09:06:12-SaleClub: Nhà khách có đám hiêú chưa xong. khách yêu cầu lắp vào ngày 25/9 ; | W8: =VLOOKUP(R8,Sheet1!$C:$D,2,0) -> TRANGDTH35
A9: 8 | B9: 11.Tay Bac Bo | C9: Tuyên Quang | D9: TQAAF1623 | E9: TIN TQG | F9: Xa Ham Yen-001- L02 | G9: Nguyen Hoai Linh | H9: Bình thường | I9: Sky F1 | J9: TQGPE00658AM:Internet | K9: Đã nhận ca | L9: 14-09-2026 07:41:40 | M9: Triển khai mới | N9: TQGP029.0026/HO-3/3-G | P9: tqg.chinhkt | Q9: Xa Ham Yen-001 | R9: TQGTI.CAOTT | S9: 30-09-2026 17:30:00 | U9: Tqfdl-260914-1623 | V9: kh chưa xđ Tgian lắp đặt>>(TQGTI.CAOTT 20/09/2026 05:00:55 PM) | W9: =VLOOKUP(R9,Sheet1!$C:$D,2,0) -> UYENHT15
A10: 9 | B10: 11.Tay Bac Bo | C10: Tuyên Quang | D10: TQAAF1600 | E10: TIN TQG | F10: Xa Phu Luong-001- L02 | G10: Do Minh Nam | H10: Bình thường | I10: Sky | J10: TQGPE0065BJ0:FPT Camera Combo, Internet | K10: Đang xử lý | L10: 14-09-2026 09:28:50 | M10: Triển khai mới | N10: TQGP026.0029/HO-11/11-G | P10: tqg.huongnt153 | Q10: Xa Phu Luong-001 | R10: TQGTI.BINHLV6 | S10: 19-09-2026 17:30:00 | U10: Tqfdl-260914-1600 | W10: =VLOOKUP(R10,Sheet1!$C:$D,2,0) -> TAMVTT5
A11: 10 | B11: 11.Tay Bac Bo | C11: Tuyên Quang | D11: TQAAF1677 | E11: TIN TQG | F11: Phuong An Tuong-001- L02 | G11: NGUYEN THO PHUONG | H11: Bình thường | I11: Giga | J11: TQGPE0065D8P:FPT Camera Combo, FPT Play, Internet | K11: Đã nhận ca | L11: 14-09-2026 11:48:54 | M11: Triển khai mới | N11: TQGP005.0314/HO-8/8-G | P11: hcm.sonlv20 | Q11: Phuong An Tuong-001 | R11: TQGTI.GIANGVH2 | S11: 30-09-2026 10:00:00 | U11: Tqfdl-260914-1677 | W11: =VLOOKUP(R11,Sheet1!$C:$D,2,0) -> ANHHV15
A12: 11 | B12: 11.Tay Bac Bo | C12: Tuyên Quang | D12: TQAAF1592 | E12: TIN TQG | F12: Xa Yen Son-001- L01 | G12: Ma Van Muoi | H12: Bình thường | I12: Giga | J12: TQGPF0065S1F:FPT Play | K12: Đã nhận ca | L12: 15-09-2026 20:34:34 | M12: KH nâng cấp dịch vụ gia tăng | N12: TQGP038.0264/HO-3/3-G | P12: tqg.tuenv3 | Q12: Xa Yen Son-001 | R12: TQGTI.CUONGDD9 | S12: 25-09-2026 10:00:00 | T12: 22-09-2026 15:30:00 | U12: Tqfdl-260911-1592 | W12: =VLOOKUP(R12,Sheet1!$C:$D,2,0) -> TRANGDTH35
A13: 12 | B13: 11.Tay Bac Bo | C13: Tuyên Quang | D13: TQAAF1767 | E13: TIN TQG | F13: Xa Ham Yen-001- L02 | G13: Nguyen Quoc Huy | H13: Bình thường | I13: Giga | J13: TQGPH0066B9D:FPT Camera Combo, FPT Play, Internet | K13: Đã nhận ca | L13: 17-09-2026 10:13:31 | M13: Triển khai mới | N13: TQGP029.0110/HO-4/4-G | P13: tqg.datnt473 | Q13: Xa Ham Yen-001 | R13: TQGTI.CAOTT | S13: 24-09-2026 17:30:00 | U13: Tqfdl-260917-1767 | V13: kh đi vắng.hẹn t3 mới về>>(TQGTI.CAOTT 20/09/2026 03:01:09 PM) | W13: =VLOOKUP(R13,Sheet1!$C:$D,2,0) -> UYENHT15
A14: 13 | B14: 11.Tay Bac Bo | C14: Tuyên Quang | D14: TQAAF1779 | E14: TIN TQG | F14: Xa Yen Son-001- L02 | G14: Do Xuan Hoa | H14: Bình thường | I14: Giga | J14: TQGPH0066BM9:FPT Play, Internet | K14: Đã nhận ca | L14: 17-09-2026 10:40:36 | M14: Triển khai mới | N14: TQGP008.0361/HO-3/3-G | P14: hni.lamtt34 | Q14: Xa Yen Son-001 | R14: TQGTI.TUNGDT4 | T14: 24-09-2026 17:30:00 | U14: Tqfdl-260917-1779 | V14: Micro-PTC-NOT-OK(TQGTI.TUNGDT4) - 21/09/2026 06:52:56; -> ; Chuyển thi công-hni.lamtt34-21/09/2026 14:45:20-SaleClub: đã mở port; | W14: =VLOOKUP(R14,Sheet1!$C:$D,2,0) -> TRANGHT28
A15: 14 | B15: 11.Tay Bac Bo | C15: Tuyên Quang | D15: TQAAF1800 | E15: TIN TQG | F15: Xa Yen Son-001- L02 | G15: Nguyen Thi Tuyen | H15: Bình thường | I15: Giga | J15: TQGPH0066CZL:FPT Camera Combo, FPT Play, Internet | K15: Đã nhận ca | L15: 17-09-2026 13:06:43 | M15: Triển khai mới | N15: TQGP008.0126/HO-15/15-G | P15: tqg.hant275 | Q15: Xa Hung Duc-001 | R15: TQGTI.TRUNGNX3 | S15: 27-09-2026 17:30:00 | U15: Tqfdl-260917-1800 | V15: Phân tuyến trên Inside TQGTI.TRUNGNX3>>(Nghiavm1.tin 24/09/2026 07:39:33 AM) Phân tuyến trên Inside TQGTI.TUNGDT4>>(Nghiavm1.tin 20/09/2026 08:06:24 AM) Phân tuyến trên Inside TQGTI.NGHIANV6>>(longtt.tin 18/09/2026 11:46:28 PM) | W15: =VLOOKUP(R15,Sheet1!$C:$D,2,0) -> TRANGHT28
A16: 15 | B16: 11.Tay Bac Bo | C16: Tuyên Quang | D16: TQAAF1774 | E16: TIN TQG | F16: Xa Yen Son-001- L02 | G16: LE THI CHANG | H16: Bình thường | I16: Sky | J16: TQGPH0066JHU:FPT Camera Combo, Internet | K16: Đã nhận ca | L16: 17-09-2026 16:08:02 | M16: Triển khai mới | N16: TQGP008.0366/HO-V/V-G | P16: tqg.oanhhtk | Q16: Xa Hung Duc-001 | R16: TQGTI.TRUNGNX3 | S16: 25-09-2026 10:00:00 | U16: Tqfdl-260917-1774 | W16: =VLOOKUP(R16,Sheet1!$C:$D,2,0) -> TRANGHT28
A17: 16 | B17: 11.Tay Bac Bo | C17: Tuyên Quang | D17: TQAAF1812 | E17: TIN TQG | F17: Phuong Minh Xuan-001- L03 | G17: LUONG THI ANH HONG | H17: Bình thường | I17: Sky | J17: TQGPH0066JYB:FPT Camera Combo, Internet | K17: Đã nhận ca | L17: 17-09-2026 16:21:12 | M17: Triển khai mới | N17: TQGP003.0175/HO-11/11-G | P17: tqg.oanhhtk | Q17: Phuong Minh Xuan-001 | R17: TQGTI.TUANQD | S17: 25-09-2026 17:30:00 | U17: Tqfdl-260917-1812 | V17: Phân tuyến trên Inside TQGTI.TUANQD>>(Nghiavm1.tin 22/09/2026 07:38:44 AM) Phân tuyến trên Inside TQGTI.THANHNV8>>(Nghiavm1.tin 20/09/2026 03:24:46 PM) Phân tuyến trên Inside TQGTI.TUANQD>>(Nghiavm1.tin 20/09/2026 02:43:34 PM) | W17: =VLOOKUP(R17,Sheet1!$C:$D,2,0) -> TRANGDTH35
A18: 17 | B18: 11.Tay Bac Bo | C18: Tuyên Quang | D18: TQAAF1839 | E18: TIN TQG | F18: Xa Phu Luong-001- L01 | G18: DAO THI DIEM | H18: Bình thường | I18: Giga | J18: TQGPH0066LV3:FPT Play, Internet | K18: Đã nhận ca | L18: 17-09-2026 19:16:30 | M18: Triển khai mới | N18: TQGP032.0178/HO-1/1-G | P18: hni.quannh79 | Q18: Xa Phu Luong-001 | R18: TQGTI.QUYETNT1 | T18: 22-09-2026 19:30:00 | U18: Tqfdl-260917-1839 | V18: khâch hen 2 3 hôm nưaz mới keo>>(TQGTI.QUYETNT1 21/09/2026 05:37:21 PM) | W18: =VLOOKUP(R18,Sheet1!$C:$D,2,0) -> TAMVTT5
A19: 18 | B19: 11.Tay Bac Bo | C19: Tuyên Quang | D19: TQAAF1494 | E19: TIN TQG | F19: Phuong Minh Xuan-001- L05 | G19: Hoang Trung Kien | H19: Bình thường | I19: Giga | J19: TQGPH0066MHU:FPT Camera Combo, FPT Play, Internet | K19: Đã nhận ca | L19: 17-09-2026 20:58:59 | M19: Triển khai mới | N19: TQGP009.0219/HO-8/8-G | P19: tqg.chinhkt | Q19: Phuong Minh Xuan-001 | R19: TQGTI.TUANQD | S19: 30-09-2026 15:30:00 | U19: Tqfdl-260909-1494 | V19: chưa nâng cấp post>>(TQGTI.TUANQD 19/09/2026 09:46:38 AM) | W19: =VLOOKUP(R19,Sheet1!$C:$D,2,0) -> TRANGDTH35
A20: 19 | B20: 11.Tay Bac Bo | C20: Tuyên Quang | D20: TQAAF1784 | E20: TIN TQG | F20: Xa Chiem Hoa-001- L04 | G20: HOANG VAN TUY | H20: Bình thường | I20: Giga | J20: TQGPI0066TSV:FPT Camera Combo, FPT Play, Internet | K20: Đã nhận ca | L20: 18-09-2026 11:52:11 | M20: Triển khai mới | N20: TQGP033.0341/HO-5/5-G | P20: hni.ngaltt13 | Q20: Xa Chiem Hoa-001 | R20: TQGTI.TIENVT3 | S20: 25-09-2026 10:00:00 | U20: Tqfdl-260918-1784 | V20: kh hẹn tháng sau thi công>>(TQGTI.TIENVT3 23/09/2026 08:35:21 AM) Phân tuyến trên Inside TQGTI.CHIENMM>>(Hahh.tin 21/09/2026 02:47:40 PM) | W20: =VLOOKUP(R20,Sheet1!$C:$D,2,0) -> UYENHT15
A21: 20 | B21: 11.Tay Bac Bo | C21: Tuyên Quang | D21: TQAAB7690 | E21: TIN TQG | F21: Xa Hung Duc-001- L02 | G21: DAO THI THAO | H21: Bình thường | I21: Giga | J21: TQGPI0066VI2:FPT Camera Combo | K21: Đã nhận ca | L21: 18-09-2026 15:14:08 | M21: KH nâng cấp dịch vụ gia tăng | N21: TQGP025.0075/HO-7/7-G | P21: hni.thuht22 | Q21: Xa Hung Duc-001 | R21: TQGTI.TRUNGNX3 | T21: 24-09-2026 19:30:00 | U21: Tqfdl-240711-7690 | V21: kh hen>>(TQGTI.TRUNGNX3 24/09/2026 11:31:03 AM) kh hẹn>>(TQGTI.TRUNGNX3 24/09/2026 02:52:40 AM) hẹn kh>>(TQGTI.TRUNGNX3 23/09/2026 05:03:01 PM) hẹn kh>>(TQGTI.TRUNGNX3 23/09/2026 03:08:34 PM) hẹn kh>>(TQGTI.TRUNGNX3 23/09/2026 11:39:44 AM) hẹn kh>>(TQGTI.TRUNGNX3 22/09/2026 07:17:13 PM) kh hen>>(TQGTI.TRUNGNX3 22/09/2026 09:32:46 AM) hẹn kh>>(TQGTI.TRUNGNX3 20/09/2026 04:49:06 PM) kh hẹn>>(TQGTI.TRUNGNX3 19/09/2026 06:51:02 PM) hẹn kh>>(TQGTI.TRUNGNX3 19/09/2026 10:22:10 AM) | W21: =VLOOKUP(R21,Sheet1!$C:$D,2,0) -> TRANGHT28
A22: 21 | B22: 11.Tay Bac Bo | C22: Tuyên Quang | D22: TQAAC0965 | E22: TIN TQG | F22: Xa Yen Son-001 | G22: NGUYEN THI XUYEN | H22: Chủ thuê bao đi vắng | I22: Giga | J22: TQGPI0066WKI:FPT Play, Internet | K22: Đã nhận ca | L22: 18-09-2026 16:35:21 | M22: Khôi phục dịch vụ | P22: tqg.huongtt33 | Q22: Phuong Minh Xuan-001 | R22: TQGTI.DANGNV | T22: 24-09-2026 15:30:00 | U22: Tqfdl-241209-0965 | V22: chưa có thiết bị>>(Nghiavm1.tin 22/09/2026 09:47:41 AM) Phân tuyến trên Inside TQGTI.THANHNV8>>(Nghiavm1.tin 21/09/2026 07:42:55 AM) | W22: =VLOOKUP(R22,Sheet1!$C:$D,2,0) -> TRANGHT28
A23: 22 | B23: 11.Tay Bac Bo | C23: Tuyên Quang | D23: TQAAF1350 | E23: TIN TQG | F23: Phuong Minh Xuan-001- L04 | G23: Tran Trung Kien | H23: Bình thường | I23: Sky | J23: TQGPI0066X4L:FPT Play | K23: Đã nhận ca | L23: 18-09-2026 17:28:12 | M23: KH nâng cấp dịch vụ gia tăng | N23: TQGP003.0080/HO-16/16-G | P23: tqg.vannt27 | Q23: Phuong Minh Xuan-001 | R23: TQGTI.DANGNV | S23: 27-09-2026 10:00:00 | U23: Tqfdl-260905-1350 | V23: ko có box>>(TQGTI.DANGNV 23/09/2026 08:31:19 AM) ko có box tsd. kt goi kh hen nhung thue bao>>(TQGTI.DANGNV 21/09/2026 09:23:50 AM) | W23: =VLOOKUP(R23,Sheet1!$C:$D,2,0) -> TRANGHT28
A24: 23 | B24: 11.Tay Bac Bo | C24: Tuyên Quang | D24: TQAAF1766 | E24: TIN TQG | F24: Phuong Minh Xuan-001- L05 | G24: Tran Duy Long | H24: Bình thường | I24: Giga | J24: TQGPJ00672M1:FPT Camera Combo, FPT Play, Internet | K24: Đã nhận ca | L24: 19-09-2026 08:04:50 | M24: Triển khai mới | N24: TQGP009.0050/HO-V/V-G | P24: tqg.tuenv3 | Q24: Phuong Minh Xuan-001 | R24: TQGTI.TUANQD | S24: 30-09-2026 12:00:00 | U24: Tqfdl-260919-1766 | W24: =VLOOKUP(R24,Sheet1!$C:$D,2,0) -> TRANGDTH35
A25: 24 | B25: 11.Tay Bac Bo | C25: Tuyên Quang | D25: TQAAF0857 | E25: TIN TQG | F25: Phuong An Tuong-001- L04 | G25: Vu Van Huy | H25: Bình thường | I25: Giga | J25: TQGPJ00674X5:FPT Play | K25: Đã nhận ca | L25: 19-09-2026 09:28:39 | M25: KH nâng cấp dịch vụ gia tăng | N25: TQGP001.0086/HO-6/6-G | P25: tqg.huongnt153 | Q25: Phuong An Tuong-001 | R25: TQGTI.CUHA | T25: 24-09-2026 17:30:00 | U25: Tqfdl-260822-0857 | V25: kho dang ko co hang>>(TQGTI.CUHA 22/09/2026 01:52:59 PM) vat tu kt dang het>>(TQGTI.CUHA 21/09/2026 04:51:37 PM) Phân tuyến trên Inside TQGTI.CUHA>>(longtt.tin 21/09/2026 09:40:22 AM) chưa có thiêt bị tương ứng hẹn lại>>(TQGTI.GIANGVH2 20/09/2026 10:38:59 AM) chưa có Tb tương ứng hẹn lại kh>>(TQGTI.GIANGVH2 19/09/2026 09:36:01 AM) | W25: =VLOOKUP(R25,Sheet1!$C:$D,2,0) -> HUONGTT33
A26: 25 | B26: 11.Tay Bac Bo | C26: Tuyên Quang | D26: TQAAF1835 | E26: TIN TQG | F26: Phuong My Lam-001- L02 | G26: Nguyen Thi Ly | H26: Bình thường | I26: Sky | J26: TQGPJ006781I:Internet | K26: Đã phân công | L26: 19-09-2026 14:28:34 | M26: Triển khai mới | N26: TQGP013.0026/HO-4/4-G | P26: tqg.hatt47 | Q26: Phuong My Lam-001 | R26: TQGTI.ANHPH3 | S26: 25-09-2026 17:30:00 | U26: Tqfdl-260919-1835 | V26: Phân tuyến trên Inside TQGTI.ANHPH3>>(Nghiavm1.tin 23/09/2026 08:13:07 AM) sale báo xin nang hộp>>(TQGTI.DANGNV 21/09/2026 11:12:30 AM) Phân tuyến trên Inside TQGTI.DANGNV>>(Nghiavm1.tin 21/09/2026 07:33:37 AM) | W26: =VLOOKUP(R26,Sheet1!$C:$D,2,0) -> HUONGTT33
A27: 26 | B27: 11.Tay Bac Bo | C27: Tuyên Quang | D27: TQFD21667 | E27: TIN TQG | F27: Xa Yen Son-001- L02 | G27: TUONG VAN NOI | H27: Bình thường | I27: Sky | J27: TQGPK0067Q7I:FPT Camera Combo | K27: Đã nhận ca | L27: 20-09-2026 18:13:06 | M27: KH nâng cấp dịch vụ gia tăng | N27: TQGP008.0314/HO-6/6-G | P27: 0858600063 | Q27: Xa Yen Son-001 | R27: TQGTI.TUNGDT4 | S27: 30-09-2026 17:30:00 | U27: Tqfdl-211010-667 | V27: kh di la,o HN chua ve khi nao vè kh lien he lqi de lap dat>>(TQGTI.TUNGDT4 23/09/2026 02:34:32 PM) | W27: =VLOOKUP(R27,Sheet1!$C:$D,2,0) -> TRANGHT28
A28: 27 | B28: 11.Tay Bac Bo | C28: Tuyên Quang | D28: TQLS00116 | E28: TIN TQG | F28: Phuong My Lam-001- L02 | G28: Pham Anh Hung | H28: Bình thường | I28: SDWAN 70 | J28: SDWAN70_88090:SDWAN70 | K28: Đã nhận ca | L28: 21-09-2026 09:01:25 | M28: Triển khai mới | N28: TQGP013.0053/HO-1/1-G | P28: LyTT11 | Q28: Phuong My Lam-001 | R28: TQGTI.QUANDM2 | S28: 25-09-2026 15:30:00 | U28: TQfdl-260916-116 | V28: Phân tuyến trên Inside TQGTI.QUANDM2>>(Nghiavm1.tin 24/09/2026 09:50:29 AM) Phân tuyến trên Inside TQGTI.ANHPH3>>(Nghiavm1.tin 23/09/2026 07:54:49 AM) | W28: =VLOOKUP(R28,Sheet1!$C:$D,2,0) -> HUONGTT33
A29: 28 | B29: 11.Tay Bac Bo | C29: Tuyên Quang | D29: TQLS00115 | E29: TIN TQG | F29: Xa Phu Luong-001- L01 | G29: Pham Anh Hung | H29: Bình thường | I29: SDWAN 70 | J29: SDWAN70_88089:SDWAN70 | K29: Đã nhận ca | L29: 21-09-2026 09:13:44 | M29: Triển khai mới | N29: TQGP031.0136/HO-2/2-G | P29: LyTT11 | Q29: Xa Phu Luong-001 | R29: TQGTI.QUYETNT1 | S29: 25-09-2026 10:00:00 | U29: TQfdl-260916-115 | W29: =VLOOKUP(R29,Sheet1!$C:$D,2,0) -> TAMVTT5
A30: 29 | B30: 11.Tay Bac Bo | C30: Tuyên Quang | D30: TQAAF1819 | E30: TIN TQG | F30: Xa Ham Yen-001- L02 | G30: Dang Van Trung | H30: Bình thường | I30: Giga | J30: TQGPL0068019:FPT Camera Combo, FPT Play, Internet | K30: Đã nhận ca | L30: 21-09-2026 10:35:22 | M30: Triển khai mới | N30: TQGP029.0384/HO-6/6-G | P30: tqg.thutt45 | Q30: Xa Ham Yen-001 | R30: TQGTI.HUNGCV4 | S30: 24-09-2026 15:30:00 | U30: Tqfdl-260921-1819 | V30: Phân tuyến trên Inside TQGTI.HUNGCV4>>(Hahh.tin 22/09/2026 08:41:10 AM) | W30: =VLOOKUP(R30,Sheet1!$C:$D,2,0) -> UYENHT15
A31: 30 | B31: 11.Tay Bac Bo | C31: Tuyên Quang | D31: TQAAF1858 | E31: TIN TQG | F31: Phuong Minh Xuan-001- L05 | G31: Ban Duc The | H31: Bình thường | I31: Giga | J31: TQGPL00680D7:FPT Camera Combo, FPT Play, Internet | K31: Đã nhận ca | L31: 21-09-2026 10:59:56 | M31: Triển khai mới | N31: TQGP009.0350/HO-1/1-G | P31: tqg.dunght29 | Q31: Phuong Minh Xuan-001 | R31: TQGTI.TUANQD | S31: 25-09-2026 17:30:00 | U31: Tqfdl-260921-1858 | W31: =VLOOKUP(R31,Sheet1!$C:$D,2,0) -> TRANGDTH35
A32: 31 | B32: 11.Tay Bac Bo | C32: Tuyên Quang | D32: TQAAE0085 | E32: TIN TQG | F32: Phuong My Lam-001- L01 | G32: NGUYEN HONG LOAN | H32: Bình thường | I32: Sky | J32: TQGPL00680FM:FPT Camera Combo | K32: Đã nhận ca | L32: 21-09-2026 11:04:47 | M32: KH nâng cấp dịch vụ gia tăng | N32: TQGP013.0239/HO-10/10-G | P32: hni.huongttt50 | Q32: Phuong My Lam-001 | R32: TQGTI.QUANDM2 | S32: 27-09-2026 10:00:00 | U32: Tqfdl-251022-0085 | V32: kt lhe khg knm, kt qua nha khg chi co ba o nha. chd di lam xa. k co nha, kt tich hen lai>>(TQGTI.QUANDM2 24/09/2026 10:25:11 AM) | W32: =VLOOKUP(R32,Sheet1!$C:$D,2,0) -> HUONGTT33
A33: 32 | B33: 11.Tay Bac Bo | C33: Tuyên Quang | D33: TQAAF1904 | E33: TIN TQG | F33: Phuong Minh Xuan-001- L04 | G33: Nguyen Tung Lam | H33: Bình thường | I33: Giga | J33: TQGPL00684EY:FPT Play, Internet | K33: Đã nhận ca | L33: 21-09-2026 17:51:36 | M33: Triển khai mới | N33: TQGP004.0182/HO-2/2-G | P33: tqg.anhpl2 | Q33: Phuong Minh Xuan-001 | R33: TQGTI.NAMVD2 | S33: 27-09-2026 17:30:00 | U33: Tqfdl-260921-1904 | V33: Phân tuyến trên Inside TQGTI.NAMVD2>>(Nghiavm1.tin 22/09/2026 07:39:02 AM) | W33: =VLOOKUP(R33,Sheet1!$C:$D,2,0) -> TRANGDTH35
A34: 33 | B34: 11.Tay Bac Bo | C34: Tuyên Quang | D34: TQAAF1878 | E34: TIN TQG | F34: Phuong My Lam-001- L03 | G34: Vuong Van Phu | H34: Bình thường | I34: Giga | J34: TQGPL00684OI:FPT Camera Combo, FPT Play, Internet | K34: Đã nhận ca | L34: 21-09-2026 18:20:00 | M34: Triển khai mới | N34: TQGP013.0223/HO-V/V-G | P34: tqg.hatt47 | Q34: Phuong My Lam-001 | R34: TQGTI.ANHPH3 | T34: 24-09-2026 17:30:00 | U34: Tqfdl-260921-1878 | V34: chua xly kip>>(TQGTI.ANHPH3 23/09/2026 05:24:45 PM) chua xly kip>>(TQGTI.ANHPH3 23/09/2026 11:48:10 AM) kh vắng nhà>>(TQGTI.THANHNV8 22/09/2026 09:13:34 AM) Phân tuyến trên Inside TQGTI.THANHNV8>>(Nghiavm1.tin 22/09/2026 08:46:43 AM) | W34: =VLOOKUP(R34,Sheet1!$C:$D,2,0) -> HUONGTT33
A35: 34 | B35: 11.Tay Bac Bo | C35: Tuyên Quang | D35: TQD000999 | E35: TIN TQG | F35: Phuong Minh Xuan-001- L04 | G35: Chau Van Thach | H35: Bình thường | I35: Giga | J35: TQGPL006858C:Sản phẩm khác | K35: Đã nhận ca | L35: 21-09-2026 19:33:55 | M35: Khách hàng mua/đổi thiết bị | N35: TQGP004.0186/HO-8/8-G | P35: hni.tin.ngocbtb1 | Q35: Phuong Minh Xuan-001 | R35: TQGTI.TUANQD | T35: 24-09-2026 17:30:00 | U35: Tqdsl-140711-999 | W35: =VLOOKUP(R35,Sheet1!$C:$D,2,0) -> TRANGDTH35
A36: 35 | B36: 11.Tay Bac Bo | C36: Tuyên Quang | D36: TQAAF1832 | E36: TIN TQG | F36: Xa Dong Tho-001- L02 | G36: NGUYEN VAN LUU | H36: Bình thường | I36: Giga | J36: TQGPL00685JH:FPT Play, Internet | K36: Đã nhận ca | L36: 21-09-2026 20:45:16 | M36: Triển khai mới | N36: TQGP032.0329/HO-V/V-G | P36: qnh.hoangbt6 | Q36: Xa Dong Tho-001 | R36: TQGTI.NGHIANV6 | S36: 26-09-2026 10:00:00 | U36: Tqfdl-260921-1832 | W36: =VLOOKUP(R36,Sheet1!$C:$D,2,0) -> LYHK7
A37: 36 | B37: 11.Tay Bac Bo | C37: Tuyên Quang | D37: TQAAF1851 | E37: TIN TQG | F37: Xa Nhu Khe-001- L02 | G37: Nguyen Thi Minh Tam | H37: Bình thường | I37: Sky | J37: TQGPL00685QY:Internet | K37: Đã nhận ca | L37: 21-09-2026 21:09:36 | M37: Triển khai mới | N37: TQGP016.0131/HO-1/1-G | P37: hcm.nguyenndk | Q37: Xa Nhu Khe-001 | R37: TQGTI.KHANHLQ1 | S37: 25-09-2026 17:30:00 | U37: Tqfdl-260921-1851 | V37: khg bao k ai ở nhà hẹn mai có ng ở nhà sẽ nhắn lại>>(TQGTI.KHANHLQ1 24/09/2026 08:59:30 AM) | W37: =VLOOKUP(R37,Sheet1!$C:$D,2,0) -> ANHHV15
A38: 37 | B38: 11.Tay Bac Bo | C38: Tuyên Quang | D38: TQAAF0835 | E38: TIN TQG | F38: Xa Son Duong-001 | G38: Hoang Huy Hung | H38: Bình thường | I38: Sky | J38: SSR-TQAAF0835-TDDDAM220926YFX1:Internet | K38: Đã nhận ca | L38: 22-09-2026 08:27:41 | M38: Chuyển địa điểm | N38: TQGP022.0319/HO-1/1-G | P38: LyHK7 | Q38: Xa Phu Luong-001 | R38: TQGTI.BINHLV6 | S38: 24-09-2026 15:30:00 | U38: Tqfdl-260821-0835 | W38: =VLOOKUP(R38,Sheet1!$C:$D,2,0) -> TAMVTT5
A39: 38 | B39: 11.Tay Bac Bo | C39: Tuyên Quang | D39: TQFD22130 | E39: TIN TQG | F39: Xa Yen Son-001- L02 | G39: BAN THI HOI | H39: Bình thường | I39: Sky | J39: TQGPM0068BAI:FPT Camera Combo | K39: Đã nhận ca | L39: 22-09-2026 09:19:10 | M39: KH nâng cấp dịch vụ gia tăng | N39: TQGP008.0225/HO-5/5-G | P39: hni.quyennt85 | Q39: Xa Yen Son-001 | R39: TQGTI.TUNGDT4 | S39: 24-09-2026 17:30:00 | U39: Tqfdl-211111-130 | V39: kh hen mai lap dat>>(TQGTI.TUNGDT4 23/09/2026 02:28:28 PM) | W39: =VLOOKUP(R39,Sheet1!$C:$D,2,0) -> TRANGHT28
A40: 39 | B40: 11.Tay Bac Bo | C40: Tuyên Quang | D40: TQAAF1884 | E40: TIN TQG | F40: Xa Chiem Hoa-001- L01 | G40: Seo Van Dai | H40: Bình thường | I40: Sky F1 | J40: TQGPM0068C3L:FPT Camera Combo, Internet | K40: Đã nhận ca | L40: 22-09-2026 10:18:17 | M40: Triển khai mới | N40: TQGP036.0345/HO-V/V-G | P40: tqg.datnt473 | Q40: Xa Chiem Hoa-001 | R40: TQGTI.HUNGDQ5 | S40: 24-09-2026 17:30:00 | U40: Tqfdl-260922-1884 | V40: Phân tuyến trên Inside TQGTI.HUNGDQ5>>(Hahh.tin 23/09/2026 09:41:19 PM) | W40: =VLOOKUP(R40,Sheet1!$C:$D,2,0) -> HUONGTT33
...

Sheet Sheet1
A1: Đã kiểm soát | C1: NS chính | D1: NS DVKH
A2: Đang kiểm soát | C2: TQGTI.GIANGVH2 | D2: ANHHV15
C3: TQGTI.THANHNV41 | D3: ANHHV15
C4: TQGTI.CAONB | D4: ANHHV15
C5: TQGTI.KHANHLQ1 | D5: ANHHV15
C6: TQGTI.CUHA | D6: HUONGTT33
C7: TQGTI.QUANDM2 | D7: HUONGTT33
C8: TQGTI.ANHPH3 | D8: HUONGTT33
C9: TQGTI.HOANQV | D9: HUONGTT33
C10: TQGTI.CHIENMM | D10: HUONGTT33
C11: TQGTI.HUNGDQ5 | D11: HUONGTT33
C12: TQGTI.CUONGLM8 | D12: LYHK7
C13: TQGTI.NGHIANV6 | D13: LYHK7
C14: TQGTI.CONGND4 | D14: LYHK7
... C35: TQGTI.HUNGCV4 | D35: UYENHT15
